<?xml version="1.0" encoding="utf-8"?>
<!-- This URDF was automatically created by SolidWorks to URDF Exporter! Originally created by Stephen Brawner (brawner@gmail.com) 
     Commit Version: 1.5.1-0-g916b5db  Build Version: 1.5.7152.31018
     For more information, please see http://wiki.ros.org/sw_urdf_exporter -->
<robot
  name="cooneo_mini">
  <link
    name="base_link">
    <inertial>
      <origin
        xyz="0.030649671440691 -1.79069899872708E-05 0.0558717976709459"
        rpy="0 0 0" />
      <mass
        value="1.72617713171385" />
      <inertia
        ixx="0.0107311274569357"
        ixy="-3.24164649120244E-08"
        ixz="0.00169188715816868"
        iyy="0.0198871551919603"
        iyz="2.40252669081509E-07"
        izz="0.0269841937242323" />
    </inertial>
    <visual>
      <origin
        xyz="0 0 0"
        rpy="0 0 0" />
      <geometry>
        <mesh
          filename="package://cooneo_mini/meshes/base_link.STL" />
      </geometry>
      <material
        name="">
        <color
          rgba="0.250980392156863 0.250980392156863 0.250980392156863 1" />
      </material>
    </visual>
    <collision>
      <origin
        xyz="0 0 0"
        rpy="0 0 0" />
      <geometry>
        <mesh
          filename="package://cooneo_mini/meshes/base_link.STL" />
      </geometry>
    </collision>
  </link>
  <link
    name="rear_wheel_link">
    <inertial>
      <origin
        xyz="-8.88178419700125E-16 -2.05391259555654E-14 -0.00112500000001892"
        rpy="0 0 0" />
      <mass
        value="5.65486677646169E-05" />
      <inertia
        ixx="1.32005796313028E-10"
        ixy="-1.938704560671E-27"
        ixz="2.13770572261755E-26"
        iyy="1.32005796313028E-10"
        iyz="-7.60216295195271E-25"
        izz="2.03575203952622E-10" />
    </inertial>
    <visual>
      <origin
        xyz="0 0 0"
        rpy="0 0 0" />
      <geometry>
        <mesh
          filename="package://cooneo_mini/meshes/rear_wheel_link.STL" />
      </geometry>
      <material
        name="">
        <color
          rgba="0.274509803921569 1 0.247058823529412 1" />
      </material>
    </visual>
    <collision>
      <origin
        xyz="0 0 0"
        rpy="0 0 0" />
      <geometry>
        <mesh
          filename="package://cooneo_mini/meshes/rear_wheel_link.STL" />
      </geometry>
    </collision>
  </link>
  <joint
    name="rear_wheel_joint"
    type="continuous">
    <origin
      xyz="-0.181499999999597 0 0.0399999999987674"
      rpy="0 0 0" />
    <parent
      link="base_link" />
    <child
      link="rear_wheel_link" />
    <axis
      xyz="0 1 0" />
  </joint>
  <link
    name="left_rear_link">
    <inertial>
      <origin
        xyz="7.85229659072684E-11 -0.0196762547002777 4.85059770127805E-11"
        rpy="0 0 0" />
      <mass
        value="0.29556182905038" />
      <inertia
        ixx="0.000374087423652291"
        ixy="2.19336154342606E-13"
        ixz="-5.50404301757561E-12"
        iyy="0.000661017199375587"
        iyz="-5.10049385981967E-14"
        izz="0.000374087441459994" />
    </inertial>
    <visual>
      <origin
        xyz="0 0 0"
        rpy="0 0 0" />
      <geometry>
        <mesh
          filename="package://cooneo_mini/meshes/left_rear_link.STL" />
      </geometry>
      <material
        name="">
        <color
          rgba="0.792156862745098 0.819607843137255 0.933333333333333 1" />
      </material>
    </visual>
    <collision>
      <origin
        xyz="0 0 0"
        rpy="0 0 0" />
      <geometry>
        <mesh
          filename="package://cooneo_mini/meshes/left_rear_link.STL" />
      </geometry>
    </collision>
  </link>
  <joint
    name="left_rear_joint"
    type="continuous">
    <origin
      xyz="-0.181499999999595 0.228542434993694 0.0399999999991634"
      rpy="0 0 0" />
    <parent
      link="base_link" />
    <child
      link="left_rear_link" />
    <axis
      xyz="0 1 0" />
    <limit
      lower="-3.14"
      upper="3.14"
      effort="0"
      velocity="0" />
  </joint>
  <link
    name="right_rear_link">
    <inertial>
      <origin
        xyz="7.8521189550429E-11 0.0196762545376323 3.35983463273237E-11"
        rpy="0 0 0" />
      <mass
        value="0.295561829050389" />
      <inertia
        ixx="0.000374087423652306"
        ixy="-2.1933774523493E-13"
        ixz="5.50404145624456E-12"
        iyy="0.000661017199375601"
        iyz="-5.10073974604221E-14"
        izz="0.000374087441459995" />
    </inertial>
    <visual>
      <origin
        xyz="0 0 0"
        rpy="0 0 0" />
      <geometry>
        <mesh
          filename="package://cooneo_mini/meshes/right_rear_link.STL" />
      </geometry>
      <material
        name="">
        <color
          rgba="0.792156862745098 0.819607843137255 0.933333333333333 1" />
      </material>
    </visual>
    <collision>
      <origin
        xyz="0 0 0"
        rpy="0 0 0" />
      <geometry>
        <mesh
          filename="package://cooneo_mini/meshes/right_rear_link.STL" />
      </geometry>
    </collision>
  </link>
  <joint
    name="right_rear_joint"
    type="continuous">
    <origin
      xyz="-0.181499999999595 -0.228542434994426 0.0399999999991584"
      rpy="0 0 0" />
    <parent
      link="base_link" />
    <child
      link="right_rear_link" />
    <axis
      xyz="0 1 0" />
    <limit
      lower="-3.14"
      upper="3.14"
      effort="0"
      velocity="0" />
  </joint>
  <link
    name="front_steer_link">
    <inertial>
      <origin
        xyz="-2.1316282072803E-14 3.67778030252452E-11 -0.00112486602459905"
        rpy="0 0 0" />
      <mass
        value="5.65486677646163E-05" />
      <inertia
        ixx="1.32005796313026E-10"
        ixy="1.16322273640277E-26"
        ixz="1.20446157864484E-28"
        iyy="1.32005796313026E-10"
        iyz="-8.66481261175625E-27"
        izz="2.03575203952619E-10" />
    </inertial>
    <visual>
      <origin
        xyz="0 0 0"
        rpy="0 0 0" />
      <geometry>
        <mesh
          filename="package://cooneo_mini/meshes/front_steer_link.STL" />
      </geometry>
      <material
        name="">
        <color
          rgba="0.274509803921569 1 0.247058823529412 1" />
      </material>
    </visual>
    <collision>
      <origin
        xyz="0 0 0"
        rpy="0 0 0" />
      <geometry>
        <mesh
          filename="package://cooneo_mini/meshes/front_steer_link.STL" />
      </geometry>
    </collision>
  </link>
  <joint
    name="front_steer_joint"
    type="revolute">
    <origin
      xyz="0.172883370897628 0 -0.00376561854722868"
      rpy="0 0 0" />
    <parent
      link="base_link" />
    <child
      link="front_steer_link" />
    <axis
      xyz="0 0 -1" />   <!-- origin xyz=0 0 1 -->
    <limit
      lower="0"
      upper="0"
      effort="0"
      velocity="0" />
  </joint>
  <link 
    name="front_steer_right_link">
    <inertial>
      <origin
        xyz="-0.00287984917571293 -0.00386608730391069 -3.40232166884391E-07"
        rpy="0 0 0" />
      <mass
        value="0.0040422891288534" />
      <inertia
        ixx="3.86012893948649E-07"
        ixy="1.06107136042318E-07"
        ixz="3.79981674665978E-12"
        iyy="5.70282019991041E-07"
        iyz="-5.11429253547313E-13"
        izz="5.85222511682915E-07" />
    </inertial>
    <visual>
      <origin
        xyz="0 0 0"
        rpy="0 0 0" />
      <geometry>
        <mesh
          filename="package://cooneo_mini/meshes/front_steer_right_link.STL" />
      </geometry>
      <material
        name="">
        <color
          rgba="0.309803921568627 1 0.333333333333333 1" />
      </material>
    </visual>
    <collision>
      <origin
        xyz="0 0 0"
        rpy="0 0 0" />
      <geometry>
        <mesh
          filename="package://cooneo_mini/meshes/front_steer_right_link.STL" />
      </geometry>
    </collision>
  </link>
  <joint
    name="front_steer_right_joint"
    type="revolute">
    <origin
      xyz="0.166956116911345 -0.155841156930144 0.0396253020756132"
      rpy="0 0 0" />
    <parent
      link="base_link" />
    <child
      link="front_steer_right_link" />
    <axis
      xyz="0 0 1" />    <!-- origin xyz=0 0 -1 -->
    <limit
      lower="-0.72"
      upper="0.72"
      effort="0"
      velocity="0" />
  </joint>
  <link
    name="front_right_wheel_link">
    <inertial>
      <origin
        xyz="9.44636555644252E-08 -0.000295273745285485 -8.13046296954667E-11"
        rpy="0 0 0" />
      <mass
        value="0.296315811300368" />
      <inertia
        ixx="0.000374692013709393"
        ixy="-9.17172260383823E-08"
        ixz="-2.43187512356516E-12"
        iyy="0.000661029987747155"
        iyz="1.9736939507106E-13"
        izz="0.000374691963930348" />
    </inertial>
    <visual>
      <origin
        xyz="0 0 0"
        rpy="0 0 0" />
      <geometry>
        <mesh
          filename="package://cooneo_mini/meshes/front_right_wheel_link.STL" />
      </geometry>
      <material
        name="">
        <color
          rgba="0.792156862745098 0.819607843137255 0.933333333333333 1" />
      </material>
    </visual>
    <collision>
      <origin
        xyz="0 0 0"
        rpy="0 0 0" />
      <geometry>
        <mesh
          filename="package://cooneo_mini/meshes/front_right_wheel_link.STL" />
      </geometry>
    </collision>
  </link>
  <joint
    name="front_right_wheel_joint"
    type="continuous">
    <origin
      xyz="0.000561692482209608 -0.0539588407104827 0"
      rpy="0 0 0" />
    <parent
      link="front_steer_right_link" />
    <child
      link="front_right_wheel_link" />
    <axis
      xyz="-0.000320310780620463 0.999999948700501 0" />
  </joint>
  <link
    name="front_steer_left_link">
    <inertial>
      <origin
        xyz="-0.00288108186855052 0.00386516380026081 3.42000268327425E-07"
        rpy="0 0 0" />
      <mass
        value="0.00404229099686961" />
      <inertia
        ixx="3.86080919831873E-07"
        ixy="-1.06166007770352E-07"
        ixz="-3.89689093687787E-12"
        iyy="5.70214085517416E-07"
        iyz="-5.05814872179496E-13"
        izz="5.85222543205337E-07" />
    </inertial>
    <visual>
      <origin
        xyz="0 0 0"
        rpy="0 0 0" />
      <geometry>
        <mesh
          filename="package://cooneo_mini/meshes/front_steer_left_link.STL" />
      </geometry>
      <material
        name="">
        <color
          rgba="0.333333333333333 1 0.309803921568627 1" />
      </material>
    </visual>
    <collision>
      <origin
        xyz="0 0 0"
        rpy="0 0 0" />
      <geometry>
        <mesh
          filename="package://cooneo_mini/meshes/front_steer_left_link.STL" />
      </geometry>
    </collision>
  </link>
  <joint
    name="front_steer_left_joint"
    type="revolute">
    <origin
      xyz="0.166955591258992 0.155840982540987 0.039624698003177"
      rpy="0 0 0" />
    <parent
      link="base_link" />
    <child
      link="front_steer_left_link" />
    <axis
      xyz="0 0 1" />   <!-- origin xyz=0 0 -1 -->
    <limit
      lower="-0.72"
      upper="0.72"
      effort="0"
      velocity="0" />
  </joint>
  <link
    name="front_left_wheel_link">
    <inertial>
      <origin
        xyz="-3.99413835339146E-11 0.000295273997845347 1.08602016268833E-10"
        rpy="0 0 0" />
      <mass
        value="0.296315811293944" />
      <inertia
        ixx="0.00037469197851121"
        ixy="-1.84493877596723E-13"
        ixz="-9.50756757097929E-12"
        iyy="0.00066103001709398"
        iyz="-1.17866882205563E-13"
        izz="0.000374691969713977" />
    </inertial>
    <visual>
      <origin
        xyz="0 0 0"
        rpy="0 0 0" />
      <geometry>
        <mesh
          filename="package://cooneo_mini/meshes/front_left_wheel_link.STL" />
      </geometry>
      <material
        name="">
        <color
          rgba="0.792156862745098 0.819607843137255 0.933333333333333 1" />
      </material>
    </visual>
    <collision>
      <origin
        xyz="0 0 0"
        rpy="0 0 0" />
      <geometry>
        <mesh
          filename="package://cooneo_mini/meshes/front_left_wheel_link.STL" />
      </geometry>
    </collision>
  </link>
  <joint
    name="front_left_wheel_joint"
    type="continuous">
    <origin
      xyz="0.000544408740910995 0.0539590174648373 0"
      rpy="0 0 0" />
    <parent
      link="front_steer_left_link" />
    <child
      link="front_left_wheel_link" />
    <axis
      xyz="0 1 0" /> <!-- origin xyz= 0 -1 0 -->
  </joint>

  <!--  手动添加激光雷达模型 -->
  <link name="laser_link">
    <visual>
      <geometry>
        <cylinder length="0.08" radius="0.05"/>
      </geometry>
    </visual>
  </link>
  <joint name ="2Dlaser_joints" type="fixed">
    <origin xyz="0.0 0.0 0.20" rpy="0.0 0.0 0.0"/>
    <parent link="base_link"/>
    <child link="laser_link"/>
  </joint>
  <!--*********************************************************************-->
 
  <!--  手动添加深度摄像头模型  -->
  <link name="deep_camera_link">
    <visual>
      <geometry>
        <mesh filename="package://cooneo_mini/meshes/kinect_Link.STL"/>
      </geometry>
    </visual>
  </link>
  <joint name ="deep_camera_joints" type="fixed">
    <origin xyz="0.10 0.0 0.17" rpy="-1.57 0.0 -1.57"/>
    <parent link="base_link"/>
    <child link="deep_camera_link"/>
  </joint>
  <!--*********************************************************************-->

 <!--  手动添加摄像头模型   -->
  <link name="camera_link">
    <visual>
      <geometry>
        <box size="0.03 0.03 0.03"/>
      </geometry>
    </visual>
  </link>
  <joint name ="camera_joints" type="fixed">
    <origin xyz="0.23 0.0 0.05" rpy="0.0 0.0 0.0"/>
    <parent link="base_link"/>
    <child link="camera_link"/>
  </joint>
  <!--*********************************************************************-->

  <!--  手动添加imu模型   -->
  <link name="imu_link">
    <visual>
      <geometry>
        <box size="0.015 0.015 0.007"/>
      </geometry>
    </visual>
  </link>
  <joint name ="imu_joints" type="fixed">
    <origin xyz="-0.10 0.0 0.12" rpy="0.0 0.0 0.0"/>
    <parent link="base_link"/>
    <child link="imu_link"/>
  </joint>
  <!--*********************************************************************-->

  <!--为link配置颜色-->
  <gazebo reference="base_link">
    <material>Gazebo/GreyTransparent </material>
  </gazebo>

  <gazebo reference="front_steer_left_link">
    <material>Gazebo/DarkGrey</material>
  </gazebo>

  <gazebo reference="front_steer_right_link">
    <material>Gazebo/DarkGrey</material>
  </gazebo>

  <gazebo reference="front_left_wheel_link">
    <material>Gazebo/Black</material>
  </gazebo>

  <gazebo reference="front_right_wheel_link">
    <material>Gazebo/Black</material>
  </gazebo>
  
  <gazebo reference="left_rear_link">
    <material>Gazebo/Black</material>
  </gazebo>

  <gazebo reference="right_rear_link">
    <material>Gazebo/Black</material>
  </gazebo>

  <gazebo reference="laser_link">
    <material>Gazebo/Black</material>
  </gazebo>

   <gazebo reference="deep_camera_link">
    <material>Gazebo/Black</material>
  </gazebo>

   <gazebo reference="camera_link">
    <material>Gazebo/Black</material>
  </gazebo>

  <gazebo reference="imu_link">
    <material>Gazebo/Black</material>
  </gazebo>
  <!--*********************************************************************-->

  <!-- 手动添加深度相机仿真插件 -->
  <gazebo reference="deep_camera_link">
    <sensor name="deep_camera" type="depth">
      <update_rate>20</update_rate>
      <camera>
        <horizontal_fov>1.047198</horizontal_fov>
        <image>
          <width>640</width>
          <height>480</height>
          <format>R8G8B8</format>
        </image>
        <clip>
          <near>0.05</near>
          <far>3</far>
        </clip>
      </camera>
      <plugin name="deep_camera_controller" filename="libgazebo_ros_openni_kinect.so">
        <baseline>0.2</baseline>
        <alwaysOn>true</alwaysOn>
        <updateRate>1.0</updateRate>
        <cameraName>/deep_camera</cameraName>
        <imageTopicName>/deep_camera/image_raw</imageTopicName>
        <cameraInfoTopicName>/deep_camera/color/camera_info</cameraInfoTopicName>
        <depthImageTopicName>/deep_camera/depth/image_raw</depthImageTopicName>
        <depthImageInfoTopicName>/deep_camera/depth/camera_info</depthImageInfoTopicName>
        <pointCloudTopicName>/deep_camera/depth/points</pointCloudTopicName>
        <frameName>deep_camera_link</frameName>
        <pointCloudCutoff>0.5</pointCloudCutoff>
        <pointCloudCutoffMax>3.0</pointCloudCutoffMax>
        <distortionK1>0.00000001</distortionK1>
        <distortionK2>0.00000001</distortionK2>
        <distortionK3>0.00000001</distortionK3>
        <distortionT1>0.00000001</distortionT1>
        <distortionT2>0.00000001</distortionT2>
        <CxPrime>0</CxPrime>
        <Cx>0</Cx>
        <Cy>0</Cy>
        <focalLength>0</focalLength>
        <hackBaseline>0</hackBaseline>
      </plugin>
    </sensor>
  </gazebo>
  <!--*********************************************************************-->

  <!-- 手动添加camera仿真插件 -->
  <gazebo reference="camera_link">
    <sensor type="camera" name="camera1">
      <update_rate>30.0</update_rate>
      <camera name="head">
        <horizontal_fov>1.3962634</horizontal_fov>
        <image>
          <width>800</width>
          <height>800</height>
          <format>R8G8B8</format>
        </image>
        <clip>
          <near>0.02</near>
          <far>300</far>
        </clip>
        <noise>
          <type>gaussian</type>
          <mean>0.0</mean>
          <stddev>0.007</stddev>
        </noise>
      </camera>
      <plugin name="camera_controller" filename="libgazebo_ros_camera.so">
        <alwaysOn>true</alwaysOn>
        <updateRate>0.0</updateRate>
        <cameraName>/camera1</cameraName>
        <imageTopicName>image_raw</imageTopicName>
        <cameraInfoTopicName>camera_info</cameraInfoTopicName>
        <frameName>base_link</frameName>
        <hackBaseline>0.07</hackBaseline>
        <distortionK1>0.0</distortionK1>
        <distortionK2>0.0</distortionK2>
        <distortionK3>0.0</distortionK3>
        <distortionT1>0.0</distortionT1>
        <distortionT2>0.0</distortionT2>
      </plugin>
    </sensor>
  </gazebo>
  <!--*********************************************************************-->

  <!-- 手动添加深激光雷达仿真插件 这里适配 rplidar A1M8 -->
  <gazebo reference="laser_link">
    <sensor type="ray" name="head_laser_sensor">
      <pose>0 0 0 0 0 0</pose>
      <visualize>false</visualize>
      <update_rate>40</update_rate>
      <ray>
        <scan>
          <horizontal>
            <samples>720</samples>
            <resolution>1</resolution>
            <min_angle>-3.1415926</min_angle>
            <max_angle>3.1415926</max_angle>
          </horizontal>
        </scan>
        <range>
          <min>0.01</min>
          <max>12.0</max>
          <resolution>0.01</resolution>
        </range>
        <noise>
          <type>gaussian</type>
          <mean>0.0</mean>
          <stddev>0.01</stddev>
        </noise>
      </ray>
      <plugin name="gazebo_ros_head_laser_controller" filename="libgazebo_ros_laser.so">
        <topicName>/scan</topicName>
        <frameName>laser_link</frameName>
      </plugin>
    </sensor>
  </gazebo>
  <!--*********************************************************************-->

  <!-- 手动添加imu仿真插件  -->
  <gazebo reference="imu_link">
    <gravity>true</gravity>
    <sensor name="imu_sensor" type="imu">
      <always_on>true</always_on>
      <update_rate>100</update_rate>
      <visualize>true</visualize>
      <topic>__default_topic__</topic>
      <plugin filename="libgazebo_ros_imu_sensor.so" name="imu_plugin">
        <topicName>imu</topicName>
        <bodyName>imu_link</bodyName>
        <updateRateHZ>10.0</updateRateHZ>
        <gaussianNoise>0.0</gaussianNoise>
        <xyzOffset>0 0 0</xyzOffset>
        <rpyOffset>0 0 0</rpyOffset>
        <frameName>imu_link</frameName>
        <initialOrientationAsReference>false</initialOrientationAsReference>
      </plugin>
      <pose>0 0 0 0 0 0</pose>
    </sensor>
  </gazebo>
  
  <!--*********************************************************************-->

  <!--  add trans plugin to front steer_joint      -->
  <transmission name="front_steer_joint_trans">
    <type>transmission_interface/SimpleTransmission</type>
    <actuator name="front_steer_joint_motor">
      <mechanicalReduction>1</mechanicalReduction>
      <hardwareInterface>hardware_interface/PositionJointInterface</hardwareInterface>
    </actuator>
    <joint name="front_steer_joint">
      <hardwareInterface>hardware_interface/PositionJointInterface</hardwareInterface>
    </joint>
  </transmission>
  <!--*********************************************************************-->

  <!-- add trans plugins to steer_joint and steer wheel joint-->
  <transmission name="front_steer_right_joint_trans">
    <type>transmission_interface/SimpleTransmission</type>
    <actuator name="front_steer_right_joint_motor">
      <mechanicalReduction>1</mechanicalReduction>
      <hardwareInterface>hardware_interface/PositionJointInterface</hardwareInterface>
    </actuator>
    <joint name="front_steer_right_joint">
      <hardwareInterface>hardware_interface/PositionJointInterface</hardwareInterface>
    </joint>
  </transmission>

  <transmission name="front_steer_left_joint_trans">
    <type>transmission_interface/SimpleTransmission</type>
    <actuator name="front_steer_left_joint_motor">
      <mechanicalReduction>1</mechanicalReduction>
      <hardwareInterface>hardware_interface/PositionJointInterface</hardwareInterface>
    </actuator>
    <joint name="front_steer_left_joint">
      <hardwareInterface>hardware_interface/PositionJointInterface</hardwareInterface>
    </joint>
  </transmission>
  <!--*********************************************************************-->

  <!-- add trans plugin to rear wheel joint-->
  <transmission name="left_rear_joint_trans">
    <type>transmission_interface/SimpleTransmission</type>
    <actuator name="left_rear_joint_motor">
      <mechanicalReduction>1</mechanicalReduction>
      <hardwareInterface>hardware_interface/VelocityJointInterface</hardwareInterface>
    </actuator>
    <joint name="left_rear_joint">
      <hardwareInterface>hardware_interface/VelocityJointInterface</hardwareInterface>
    </joint>
  </transmission>

  <transmission name="right_rear_joint_trans">
    <type>transmission_interface/SimpleTransmission</type>
    <actuator name="right_rear_joint_motor">
      <mechanicalReduction>1</mechanicalReduction>
      <hardwareInterface>hardware_interface/VelocityJointInterface</hardwareInterface>
    </actuator>
    <joint name="right_rear_joint">
      <hardwareInterface>hardware_interface/VelocityJointInterface</hardwareInterface>
    </joint>
  </transmission>
  <!--*********************************************************************-->

  <!--  add gazebo_ros_control plugin -->
  <gazebo>
    <plugin name="gazebo_ros_control" filename="libgazebo_ros_control.so">
      <robotNamespace>/</robotNamespace>
      <robotSimType>steer_bot_hardware_gazebo/SteerBotHardwareGazebo</robotSimType>
    </plugin>
  </gazebo>
  <!--*********************************************************************-->



</robot>
