<?xml version="1.0" encoding="utf-8"?>
<!-- This URDF was automatically created by SolidWorks to URDF Exporter! Originally created by Stephen Brawner (brawner@gmail.com) 
     Commit Version: 1.5.1-0-g916b5db  Build Version: 1.5.7152.31018
     For more information, please see http://wiki.ros.org/sw_urdf_exporter -->
<robot
  name="cooneo_mini">
  <link
    name="base_link">
    <inertial>
      <origin
        xyz="0.030649671440691 -1.79069899872708E-05 0.0558717976709459"
        rpy="0 0 0" />
      <mass
        value="1.72617713171385" />
      <inertia
        ixx="0.0107311274569357"
        ixy="-3.24164649120244E-08"
        ixz="0.00169188715816868"
        iyy="0.0198871551919603"
        iyz="2.40252669081509E-07"
        izz="0.0269841937242323" />
    </inertial>
    <visual>
      <origin
        xyz="0 0 0"
        rpy="0 0 0" />
      <geometry>
        <mesh
          filename="package://cooneo_mini/meshes/base_link.STL" />
      </geometry>
      <material
        name="">
        <color
          rgba="0.250980392156863 0.250980392156863 0.250980392156863 1" />
      </material>
    </visual>
    <collision>
      <origin
        xyz="0 0 0"
        rpy="0 0 0" />
      <geometry>
        <mesh
          filename="package://cooneo_mini/meshes/base_link.STL" />
      </geometry>
    </collision>
  </link>
  <link
    name="rear_wheel_link">
    <inertial>
      <origin
        xyz="-8.88178419700125E-16 -2.05391259555654E-14 -0.00112500000001892"
        rpy="0 0 0" />
      <mass
        value="5.65486677646169E-05" />
      <inertia
        ixx="1.32005796313028E-10"
        ixy="-1.938704560671E-27"
        ixz="2.13770572261755E-26"
        iyy="1.32005796313028E-10"
        iyz="-7.60216295195271E-25"
        izz="2.03575203952622E-10" />
    </inertial>
    <visual>
      <origin
        xyz="0 0 0"
        rpy="0 0 0" />
      <geometry>
        <mesh
          filename="package://cooneo_mini/meshes/rear_wheel_link.STL" />
      </geometry>
      <material
        name="">
        <color
          rgba="0.274509803921569 1 0.247058823529412 1" />
      </material>
    </visual>
    <collision>
      <origin
        xyz="0 0 0"
        rpy="0 0 0" />
      <geometry>
        <mesh
          filename="package://cooneo_mini/meshes/rear_wheel_link.STL" />
      </geometry>
    </collision>
  </link>
  <joint
    name="rear_wheel_joint"
    type="continuous">
    <origin
      xyz="-0.181499999999597 0 0.0399999999987674"
      rpy="0 0 0" />
    <parent
      link="base_link" />
    <child
      link="rear_wheel_link" />
    <axis
      xyz="0 1 0" />
  </joint>
  <link
    name="left_rear_link">
    <inertial>
      <origin
        xyz="7.85229659072684E-11 -0.0196762547002777 4.85059770127805E-11"
        rpy="0 0 0" />
      <mass
        value="0.29556182905038" />
      <inertia
        ixx="0.000374087423652291"
        ixy="2.19336154342606E-13"
        ixz="-5.50404301757561E-12"
        iyy="0.000661017199375587"
        iyz="-5.10049385981967E-14"
        izz="0.000374087441459994" />
    </inertial>
    <visual>
      <origin
        xyz="0 0 0"
        rpy="0 0 0" />
      <geometry>
        <mesh
          filename="package://cooneo_mini/meshes/left_rear_link.STL" />
      </geometry>
      <material
        name="">
        <color
          rgba="0.792156862745098 0.819607843137255 0.933333333333333 1" />
      </material>
    </visual>
    <collision>
      <origin
        xyz="0 0 0"
        rpy="0 0 0" />
      <geometry>
        <mesh
          filename="package://cooneo_mini/meshes/left_rear_link.STL" />
      </geometry>
    </collision>
  </link>
  <joint
    name="left_rear_joint"
    type="continuous">
    <origin
      xyz="-0.181499999999595 0.228542434993694 0.0399999999991634"
      rpy="0 0 0" />
    <parent
      link="base_link" />
    <child
      link="left_rear_link" />
    <axis
      xyz="0 1 0" />
    <limit
      lower="-3.14"
      upper="3.14"
      effort="0"
      velocity="0" />
  </joint>
  <link
    name="right_rear_link">
    <inertial>
      <origin
        xyz="7.8521189550429E-11 0.0196762545376323 3.35983463273237E-11"
        rpy="0 0 0" />
      <mass
        value="0.295561829050389" />
      <inertia
        ixx="0.000374087423652306"
        ixy="-2.1933774523493E-13"
        ixz="5.50404145624456E-12"
        iyy="0.000661017199375601"
        iyz="-5.10073974604221E-14"
        izz="0.000374087441459995" />
    </inertial>
    <visual>
      <origin
        xyz="0 0 0"
        rpy="0 0 0" />
      <geometry>
        <mesh
          filename="package://cooneo_mini/meshes/right_rear_link.STL" />
      </geometry>
      <material
        name="">
        <color
          rgba="0.792156862745098 0.819607843137255 0.933333333333333 1" />
      </material>
    </visual>
    <collision>
      <origin
        xyz="0 0 0"
        rpy="0 0 0" />
      <geometry>
        <mesh
          filename="package://cooneo_mini/meshes/right_rear_link.STL" />
      </geometry>
    </collision>
  </link>
  <joint
    name="right_rear_joint"
    type="continuous">
    <origin
      xyz="-0.181499999999595 -0.228542434994426 0.0399999999991584"
      rpy="0 0 0" />
    <parent
      link="base_link" />
    <child
      link="right_rear_link" />
    <axis
      xyz="0 1 0" />
    <limit
      lower="-3.14"
      upper="3.14"
      effort="0"
      velocity="0" />
  </joint>
  <link
    name="front_steer_link">
    <inertial>
      <origin
        xyz="-2.1316282072803E-14 3.67778030252452E-11 -0.00112486602459905"
        rpy="0 0 0" />
      <mass
        value="5.65486677646163E-05" />
      <inertia
        ixx="1.32005796313026E-10"
        ixy="1.16322273640277E-26"
        ixz="1.20446157864484E-28"
        iyy="1.32005796313026E-10"
        iyz="-8.66481261175625E-27"
        izz="2.03575203952619E-10" />
    </inertial>
    <visual>
      <origin
        xyz="0 0 0"
        rpy="0 0 0" />
      <geometry>
        <mesh
          filename="package://cooneo_mini/meshes/front_steer_link.STL" />
      </geometry>
      <material
        name="">
        <color
          rgba="0.274509803921569 1 0.247058823529412 1" />
      </material>
    </visual>
    <collision>
      <origin
        xyz="0 0 0"
        rpy="0 0 0" />
      <geometry>
        <mesh
          filename="package://cooneo_mini/meshes/front_steer_link.STL" />
      </geometry>
    </collision>
  </link>
  <joint
    name="front_steer_joint"
    type="revolute">
    <origin
      xyz="0.172883370897628 0 -0.00376561854722868"
      rpy="0 0 0" />
    <parent
      link="base_link" />
    <child
      link="front_steer_link" />
    <axis
      xyz="0 0 1" />
    <limit
      lower="0"
      upper="0"
      effort="0"
      velocity="0" />
  </joint>
  <link 
    name="front_steer_right_link">
    <inertial>
      <origin
        xyz="-0.00287984917571293 -0.00386608730391069 -3.40232166884391E-07"
        rpy="0 0 0" />
      <mass
        value="0.0040422891288534" />
      <inertia
        ixx="3.86012893948649E-07"
        ixy="1.06107136042318E-07"
        ixz="3.79981674665978E-12"
        iyy="5.70282019991041E-07"
        iyz="-5.11429253547313E-13"
        izz="5.85222511682915E-07" />
    </inertial>
    <visual>
      <origin
        xyz="0 0 0"
        rpy="0 0 0" />
      <geometry>
        <mesh
          filename="package://cooneo_mini/meshes/front_steer_right_link.STL" />
      </geometry>
      <material
        name="">
        <color
          rgba="0.309803921568627 1 0.333333333333333 1" />
      </material>
    </visual>
    <collision>
      <origin
        xyz="0 0 0"
        rpy="0 0 0" />
      <geometry>
        <mesh
          filename="package://cooneo_mini/meshes/front_steer_right_link.STL" />
      </geometry>
    </collision>
  </link>
  <joint
    name="front_steer_right_joint"
    type="revolute">
    <origin
      xyz="0.166956116911345 -0.155841156930144 0.0396253020756132"
      rpy="0 0 0" />
    <parent
      link="base_link" />
    <child
      link="front_steer_right_link" />
    <axis
      xyz="0 0 1" />   <!-- xyz=0 0 -1 -->
    <limit
      lower="-0.72"
      upper="0.72"
      effort="0"
      velocity="0" />
  </joint>
  <link
    name="front_right_wheel_link">
    <inertial>
      <origin
        xyz="9.44636555644252E-08 -0.000295273745285485 -8.13046296954667E-11"
        rpy="0 0 0" />
      <mass
        value="0.296315811300368" />
      <inertia
        ixx="0.000374692013709393"
        ixy="-9.17172260383823E-08"
        ixz="-2.43187512356516E-12"
        iyy="0.000661029987747155"
        iyz="1.9736939507106E-13"
        izz="0.000374691963930348" />
    </inertial>
    <visual>
      <origin
        xyz="0 0 0"
        rpy="0 0 0" />
      <geometry>
        <mesh
          filename="package://cooneo_mini/meshes/front_right_wheel_link.STL" />
      </geometry>
      <material
        name="">
        <color
          rgba="0.792156862745098 0.819607843137255 0.933333333333333 1" />
      </material>
    </visual>
    <collision>
      <origin
        xyz="0 0 0"
        rpy="0 0 0" />
      <geometry>
        <mesh
          filename="package://cooneo_mini/meshes/front_right_wheel_link.STL" />
      </geometry>
    </collision>
  </link>
  <joint
    name="front_right_wheel_joint"
    type="continuous">
    <origin
      xyz="0.000561692482209608 -0.0539588407104827 0"
      rpy="0 0 0" />
    <parent
      link="front_steer_right_link" />
    <child
      link="front_right_wheel_link" />
    <axis
      xyz="-0.000320310780620463 0.999999948700501 0" />
  </joint>
  <link
    name="front_steer_left_link">
    <inertial>
      <origin
        xyz="-0.00288108186855052 0.00386516380026081 3.42000268327425E-07"
        rpy="0 0 0" />
      <mass
        value="0.00404229099686961" />
      <inertia
        ixx="3.86080919831873E-07"
        ixy="-1.06166007770352E-07"
        ixz="-3.89689093687787E-12"
        iyy="5.70214085517416E-07"
        iyz="-5.05814872179496E-13"
        izz="5.85222543205337E-07" />
    </inertial>
    <visual>
      <origin
        xyz="0 0 0"
        rpy="0 0 0" />
      <geometry>
        <mesh
          filename="package://cooneo_mini/meshes/front_steer_left_link.STL" />
      </geometry>
      <material
        name="">
        <color
          rgba="0.333333333333333 1 0.309803921568627 1" />
      </material>
    </visual>
    <collision>
      <origin
        xyz="0 0 0"
        rpy="0 0 0" />
      <geometry>
        <mesh
          filename="package://cooneo_mini/meshes/front_steer_left_link.STL" />
      </geometry>
    </collision>
  </link>
  <joint
    name="front_steer_left_joint"
    type="revolute">
    <origin
      xyz="0.166955591258992 0.155840982540987 0.039624698003177"
      rpy="0 0 0" />
    <parent
      link="base_link" />
    <child
      link="front_steer_left_link" />
    <axis
      xyz="0 0 1" />   <!-- xyz= 0 0 -1-->
    <limit
      lower="-0.72"
      upper="0.72"
      effort="0"
      velocity="0" />
  </joint>
  <link
    name="front_left_wheel_link">
    <inertial>
      <origin
        xyz="-3.99413835339146E-11 0.000295273997845347 1.08602016268833E-10"
        rpy="0 0 0" />
      <mass
        value="0.296315811293944" />
      <inertia
        ixx="0.00037469197851121"
        ixy="-1.84493877596723E-13"
        ixz="-9.50756757097929E-12"
        iyy="0.00066103001709398"
        iyz="-1.17866882205563E-13"
        izz="0.000374691969713977" />
    </inertial>
    <visual>
      <origin
        xyz="0 0 0"
        rpy="0 0 0" />
      <geometry>
        <mesh
          filename="package://cooneo_mini/meshes/front_left_wheel_link.STL" />
      </geometry>
      <material
        name="">
        <color
          rgba="0.792156862745098 0.819607843137255 0.933333333333333 1" />
      </material>
    </visual>
    <collision>
      <origin
        xyz="0 0 0"
        rpy="0 0 0" />
      <geometry>
        <mesh
          filename="package://cooneo_mini/meshes/front_left_wheel_link.STL" />
      </geometry>
    </collision>
  </link>
  <joint
    name="front_left_wheel_joint"
    type="continuous">
    <origin
      xyz="0.000544408740910995 0.0539590174648373 0"
      rpy="0 0 0" />
    <parent
      link="front_steer_left_link" />
    <child
      link="front_left_wheel_link" />
    <axis
      xyz="0 1 0" />   <!-- xyz="0 -1 0"-->
  </joint>
</robot>
